<?xml version="1.0"?>
<robot xmlns:xacro="http://ros.org/wiki/xacro">

  <xacro:macro name="fanuc" params="parent">
   
    <!-- Joint 1 -->
    <xacro:property name="joint1upper" value="${2*pi}"/>
    <xacro:property name="joint1lower" value="${-2*pi}"/>
    <xacro:property name="joint1velocity" value="7.85"/>
    <xacro:property name="joint1effort" value="-1"/>

    <!-- Joint 2 -->
    <xacro:property name="joint2upper" value="${2*pi}"/>
    <xacro:property name="joint2lower" value="${-2*pi}"/>
    <xacro:property name="joint2velocity" value="6.63"/>
    <xacro:property name="joint2effort" value="-1"/>

    <!-- Joint 3 -->
    <xacro:property name="joint3upper" value="${2*pi}"/>
    <xacro:property name="joint3lower" value="${-2*pi}"/>
    <xacro:property name="joint3velocity" value="9.08"/>
    <xacro:property name="joint3effort" value="-1"/>

    <!-- Joint 4 -->
    <xacro:property name="joint4upper" value="${2*pi}"/>
    <xacro:property name="joint4lower" value="${-2*pi}"/>
    <xacro:property name="joint4velocity" value="9.60"/>
    <xacro:property name="joint4effort" value="-1"/>

    <!-- Joint 5 -->
    <xacro:property name="joint5upper" value="${2*pi}"/>
    <xacro:property name="joint5lower" value="${-2*pi}"/>
    <xacro:property name="joint5velocity" value="9.51"/>
    <xacro:property name="joint5effort" value="-1"/>

    <!-- Joint 6 -->
    <xacro:property name="joint6upper" value="${2*pi}"/>
    <xacro:property name="joint6lower" value="${-2*pi}"/>
    <xacro:property name="joint6velocity" value="17.45"/>
    <xacro:property name="joint6effort" value="-1"/>

    <!-- links -->
    <link name="fanuc_base_link">
      <visual>
        <origin rpy="0 0 0" xyz="0 0 0" />
        <geometry>
          <mesh filename="file://$(find fanuc_description)/meshes/visual/base_link.stl" />
        </geometry>
        <material name="">
          <color rgba="0.278431372549 0.278431372549 0.278431372549 1.0" />
        </material>
      </visual>
      
      <collision>
        <origin rpy="0 0 0" xyz="0 0 0" />
        <geometry>
          <mesh filename="file://$(find fanuc_description)/meshes/collision/base_link.stl" />
        </geometry>
      </collision>
      
      <inertial>
        <mass value="0.1" />
        <inertia ixx="0.03" iyy="0.03" izz="0.03" ixy="0.0" ixz="0.0" iyz="0.0" />
      </inertial>
    </link>

    <link name="link_1">
      <visual>
        <origin rpy="0 0 0" xyz="0 0 0" />
        <geometry>
          <mesh filename="file://$(find fanuc_description)/meshes/visual/link_1.stl" />
        </geometry>
        <material name="">
          <color rgba="0.96 0.76 0.13 1.0" />
        </material>
      </visual>
      
      <collision>
        <origin rpy="0 0 0" xyz="0 0 0" />
        <geometry>
            <mesh filename="file://$(find fanuc_description)/meshes/collision/link_1.stl" />
        </geometry>
      </collision>
      
      <inertial>
        <origin xyz="0 0 0" rpy="0 0 0" />
        <mass value="1" />
        <inertia ixx="0.0226667" ixy="0.0" ixz="0.0" iyy="0.0226667" iyz="0.0" izz="0.0226667" />
      </inertial>
    </link>

    <link name="link_2">
      <visual>
        <origin rpy="0 0 0" xyz="0 0 0" />
        <geometry>
          <mesh filename="file://$(find fanuc_description)/meshes/visual/link_2.stl" />
        </geometry>
        <material name="">
          <color rgba="0.96 0.76 0.13 1.0" />
        </material>
      </visual>

      <collision>
        <origin rpy="0 0 0" xyz="0 0 0" />
        <geometry>
          <mesh filename="file://$(find fanuc_description)/meshes/collision/link_2.stl" />
        </geometry>
      </collision>

      <inertial>
        <origin xyz="0 0 0" rpy="0 0 0" />
        <mass value="1" />
        <inertia ixx="0.0226667" ixy="0.0" ixz="0.0" iyy="0.0226667" iyz="0.0" izz="0.0226667" />
      </inertial>
    </link>

    <link name="link_3">
        <visual>
          <origin rpy="0 0 0" xyz="0 0 0" />
          <geometry>
              <mesh filename="file://$(find fanuc_description)/meshes/visual/link_3.stl" />
          </geometry>
          <material name="">
              <color rgba="0.96 0.76 0.13 1.0" />
          </material>
        </visual>
        <collision>
          <origin rpy="0 0 0" xyz="0 0 0" />
          <geometry>
              <mesh filename="file://$(find fanuc_description)/meshes/collision/link_3.stl" />
          </geometry>
        </collision>
        <inertial>
          <origin xyz="0 0 0" rpy="0 0 0" />
          <mass value="1" />
          <inertia ixx="0.0226667" ixy="0.0" ixz="0.0" iyy="0.0226667" iyz="0.0" izz="0.0226667" />
        </inertial>
    </link>

    <link name="link_4">
      <visual>
        <origin rpy="0 0 0" xyz="0 0 0" />
        <geometry>
          <mesh filename="file://$(find fanuc_description)/meshes/visual/link_4.stl" />
        </geometry>
        <material name="">
          <color rgba="0.96 0.76 0.13 1.0" />
        </material>
      </visual>

      <collision>
        <origin rpy="0 0 0" xyz="0 0 0" />
        <geometry>
          <mesh filename="file://$(find fanuc_description)/meshes/collision/link_4.stl" />
        </geometry>
      </collision>

      <inertial>
        <origin xyz="0 0 0" rpy="0 0 0" />
        <mass value="1" />
        <inertia ixx="0.0226667" ixy="0.0" ixz="0.0" iyy="0.0226667" iyz="0.0" izz="0.0226667" />
      </inertial>
    </link>

    <link name="link_5">
      <visual>
        <origin rpy="0 0 0" xyz="0 0 0" />
        <geometry>
          <mesh filename="file://$(find fanuc_description)/meshes/visual/link_5.stl" />
        </geometry>
        <material name="">
          <color rgba="0.96 0.76 0.13 1.0" />
        </material>
      </visual>

      <collision>
        <origin rpy="0 0 0" xyz="0 0 0" />
        <geometry>
            <mesh filename="file://$(find fanuc_description)/meshes/collision/link_5.stl" />
        </geometry>
      </collision>

      <inertial>
        <origin xyz="0 0 0" rpy="0 0 0" />
        <mass value="1" />
        <inertia ixx="0.0226667" ixy="0.0" ixz="0.0" iyy="0.0226667" iyz="0.0" izz="0.0226667" />
      </inertial>
    </link>

    <link name="link_6">
      <visual>
        <origin rpy="0 0 0" xyz="0 0 0" />
        <geometry>
          <mesh filename="file://$(find fanuc_description)/meshes/visual/link_6.stl" />
        </geometry>
        <material name="">
            <color rgba="0.15 0.15 0.15 1.0" />
        </material>
      </visual>

      <collision>
        <origin rpy="0 0 0" xyz="0 0 0" />
        <geometry>
          <mesh filename="file://$(find fanuc_description)/meshes/collision/link_6.stl" />
        </geometry>
      </collision>

      <inertial>
        <origin xyz="0 0 0" rpy="0 0 0" />
        <mass value="1" />
        <inertia ixx="0.0226667" ixy="0.0" ixz="0.0" iyy="0.0226667" iyz="0.0" izz="0.0226667" />
      </inertial>
    </link>

    <!-- joints --> 
    <joint name = "base_joint_" type = "fixed">
      <origin rpy = "0 0 0" xyz = "0 0 0"/>
      <parent link = "${parent}"/>
      <child link = "fanuc_base_link"/>
    </joint>

    <joint name="joint_1" type="revolute">
        <origin xyz="0 0 0.330" rpy="0 0 0" />
        <parent link="fanuc_base_link" />
        <child link="link_1" />
        <axis xyz="0 0 1" />
        <limit effort="${joint1effort}" lower="${joint1lower}" upper="${joint1upper}" velocity="${joint1velocity}" />
    </joint>
    
    <joint name="joint_2" type="revolute">
        <origin xyz="0.050 0 0" rpy="0 0 0"/>
        <parent link="link_1" />
        <child link="link_2" />
        <axis xyz="0 1 0" />
        <limit effort="${joint2effort}" lower="${joint2lower}" upper="${joint2upper}" velocity="${joint2velocity}" />
    </joint>
    
    <joint name="joint_3" type="revolute">
        <origin xyz="0 0 0.330" rpy="0 0 0"/>
        <parent link="link_2" />
        <child link="link_3" />
        <axis xyz="0 -1 0" />
        <limit effort="${joint3effort}" lower="${joint3lower}" upper="${joint3upper}" velocity="${joint3velocity}" />
    </joint>
    
    <joint name="joint_4" type="revolute">
        <origin xyz="0 0 0.035" rpy="0 0 0"/>
        <parent link="link_3"/>
        <child link="link_4"/>
        <axis xyz="-1 0 0"/>
        <limit effort="${joint4effort}" lower="${joint4lower}" upper="${joint4upper}" velocity="${joint4velocity}" />
    </joint>
    
    <joint name="joint_5" type="revolute">
        <origin xyz="0.335 0 0" rpy="0 0 0"/>
        <parent link="link_4"/>
        <child link="link_5"/>
        <axis xyz="0 -1 0"/>
        <limit effort="${joint5effort}" lower="${joint5lower}" upper="${joint5upper}" velocity="${joint5velocity}" />
    </joint>
    
    <joint name="joint_6" type="revolute">
        <origin xyz="0.080 0 0" rpy="0 0 0"/>
        <parent link="link_5"/>
        <child link="link_6"/>
        <axis xyz="-1 0 0"/>
        <limit effort="${joint6effort}" lower="${joint6lower}" upper="${joint6upper}" velocity="${joint6velocity}" />
    </joint>

  </xacro:macro>

</robot>
